Exception in thread django-main-thread:
Traceback (most recent call last):
  File "/nix/store/7d088dip86hlzri9sk0h78b63yfmx0a0-python3-3.11.13/lib/python3.11/threading.py", line 1045, in _bootstrap_inner
    self.run()
  File "/nix/store/7d088dip86hlzri9sk0h78b63yfmx0a0-python3-3.11.13/lib/python3.11/threading.py", line 982, in run
    self._target(*self._args, **self._kwargs)
  File "/home/runner/workspace/.pythonlibs/lib/python3.11/site-packages/django/utils/autoreload.py", line 64, in wrapper
    fn(*args, **kwargs)
  File "/home/runner/workspace/.pythonlibs/lib/python3.11/site-packages/django/core/management/commands/runserver.py", line 133, in inner_run
    self.check(display_num_errors=True)
  File "/home/runner/workspace/.pythonlibs/lib/python3.11/site-packages/django/core/management/base.py", line 556, in check
    raise SystemCheckError(msg)
django.core.management.base.SystemCheckError: SystemCheckError: System check identified some issues:

ERRORS:
<class 'api.admin.UserAdmin'>: (admin.E108) The value of 'list_display[4]' refers to 'is_admin', which is not a callable, an attribute of 'UserAdmin', or an attribute or method on 'api.User'.
<class 'api.admin.UserAdmin'>: (admin.E116) The value of 'list_filter[0]' refers to 'is_admin', which does not refer to a Field.

System check identified 2 issues (0 silenced).
/home/runner/workspace/wayuu_artesania/settings.py changed, reloading.
Watching for file changes with StatReloader
Performing system checks...

System check identified no issues (0 silenced).

You have 22 unapplied migration(s). Your project may not work properly until you apply the migrations for app(s): admin, api, auth, authtoken, contenttypes, sessions.
Run 'python manage.py migrate' to apply them.
July 25, 2025 - 15:10:22
Django version 4.2.7, using settings 'wayuu_artesania.settings'
Starting development server at http://0.0.0.0:3000/
Quit the server with CONTROL-C.

Internal Server Error: /
Traceback (most recent call last):
  File "/home/runner/workspace/.pythonlibs/lib/python3.11/site-packages/django/db/backends/utils.py", line 89, in _execute
    return self.cursor.execute(sql, params)
           ^^^^^^^^^^^^^^^^^^^^^^^^^^^^^^^^
  File "/home/runner/workspace/.pythonlibs/lib/python3.11/site-packages/django/db/backends/sqlite3/base.py", line 328, in execute
    return super().execute(query, params)
           ^^^^^^^^^^^^^^^^^^^^^^^^^^^^^^
sqlite3.OperationalError: no such table: api_product

The above exception was the direct cause of the following exception:

Traceback (most recent call last):
  File "/home/runner/workspace/.pythonlibs/lib/python3.11/site-packages/django/core/handlers/exception.py", line 55, in inner
    response = get_response(request)
               ^^^^^^^^^^^^^^^^^^^^^
  File "/home/runner/workspace/.pythonlibs/lib/python3.11/site-packages/django/core/handlers/base.py", line 197, in _get_response
    response = wrapped_callback(request, *callback_args, **callback_kwargs)
               ^^^^^^^^^^^^^^^^^^^^^^^^^^^^^^^^^^^^^^^^^^^^^^^^^^^^^^^^^^^^
  File "/home/runner/workspace/api/template_views.py", line 21, in home
    if not featured_products.exists():
           ^^^^^^^^^^^^^^^^^^^^^^^^^^
  File "/home/runner/workspace/.pythonlibs/lib/python3.11/site-packages/django/db/models/query.py", line 1241, in exists
    return self.query.has_results(using=self.db)
           ^^^^^^^^^^^^^^^^^^^^^^^^^^^^^^^^^^^^^
  File "/home/runner/workspace/.pythonlibs/lib/python3.11/site-packages/django/db/models/sql/query.py", line 598, in has_results
    return compiler.has_results()
           ^^^^^^^^^^^^^^^^^^^^^^
  File "/home/runner/workspace/.pythonlibs/lib/python3.11/site-packages/django/db/models/sql/compiler.py", line 1530, in has_results
    return bool(self.execute_sql(SINGLE))
                ^^^^^^^^^^^^^^^^^^^^^^^^
  File "/home/runner/workspace/.pythonlibs/lib/python3.11/site-packages/django/db/models/sql/compiler.py", line 1562, in execute_sql
    cursor.execute(sql, params)
  File "/home/runner/workspace/.pythonlibs/lib/python3.11/site-packages/django/db/backends/utils.py", line 102, in execute
    return super().execute(sql, params)
           ^^^^^^^^^^^^^^^^^^^^^^^^^^^^
  File "/home/runner/workspace/.pythonlibs/lib/python3.11/site-packages/django/db/backends/utils.py", line 67, in execute
    return self._execute_with_wrappers(
           ^^^^^^^^^^^^^^^^^^^^^^^^^^^^
  File "/home/runner/workspace/.pythonlibs/lib/python3.11/site-packages/django/db/backends/utils.py", line 80, in _execute_with_wrappers
    return executor(sql, params, many, context)
           ^^^^^^^^^^^^^^^^^^^^^^^^^^^^^^^^^^^^
  File "/home/runner/workspace/.pythonlibs/lib/python3.11/site-packages/django/db/backends/utils.py", line 84, in _execute
    with self.db.wrap_database_errors:
  File "/home/runner/workspace/.pythonlibs/lib/python3.11/site-packages/django/db/utils.py", line 91, in __exit__
    raise dj_exc_value.with_traceback(traceback) from exc_value
  File "/home/runner/workspace/.pythonlibs/lib/python3.11/site-packages/django/db/backends/utils.py", line 89, in _execute
    return self.cursor.execute(sql, params)
           ^^^^^^^^^^^^^^^^^^^^^^^^^^^^^^^^
  File "/home/runner/workspace/.pythonlibs/lib/python3.11/site-packages/django/db/backends/sqlite3/base.py", line 328, in execute
    return super().execute(query, params)
           ^^^^^^^^^^^^^^^^^^^^^^^^^^^^^^
django.db.utils.OperationalError: no such table: api_product
[25/Jul/2025 15:10:23] "GET / HTTP/1.1" 500 139969
/home/runner/workspace/api/models.py changed, reloading.
Watching for file changes with StatReloader
Performing system checks...

Exception in thread django-main-thread:
Traceback (most recent call last):
  File "/nix/store/7d088dip86hlzri9sk0h78b63yfmx0a0-python3-3.11.13/lib/python3.11/threading.py", line 1045, in _bootstrap_inner
    self.run()
  File "/nix/store/7d088dip86hlzri9sk0h78b63yfmx0a0-python3-3.11.13/lib/python3.11/threading.py", line 982, in run
    self._target(*self._args, **self._kwargs)
  File "/home/runner/workspace/.pythonlibs/lib/python3.11/site-packages/django/utils/autoreload.py", line 64, in wrapper
    fn(*args, **kwargs)
  File "/home/runner/workspace/.pythonlibs/lib/python3.11/site-packages/django/core/management/commands/runserver.py", line 133, in inner_run
    self.check(display_num_errors=True)
  File "/home/runner/workspace/.pythonlibs/lib/python3.11/site-packages/django/core/management/base.py", line 556, in check
    raise SystemCheckError(msg)
django.core.management.base.SystemCheckError: SystemCheckError: System check identified some issues:

ERRORS:
<class 'api.admin.UserAdmin'>: (admin.E108) The value of 'list_display[4]' refers to 'is_admin', which is not a callable, an attribute of 'UserAdmin', or an attribute or method on 'api.User'.
<class 'api.admin.UserAdmin'>: (admin.E116) The value of 'list_filter[0]' refers to 'is_admin', which does not refer to a Field.

System check identified 2 issues (0 silenced).
^C